<?xml version="1.0"?>
<robot xmlns:xacro="http://www.ros.org/wiki/xacro" name="mecanum_bot">

    <xacro:property name="PI" value="3.1415926535897931"/>

    <xacro:property name="chassis_length" value="0.265"/>
    <xacro:property name="chassis_width" value="0.25"/>
    <xacro:property name="chassis_height" value="0.18"/> <xacro:property name="ground_clearance" value="0.03"/>

    <xacro:property name="wheel_radius" value="0.04"/>
    <xacro:property name="wheel_width" value="0.037"/>
    <xacro:property name="wheel_separation_x" value="0.165"/> <xacro:property name="wheel_separation_y" value="0.215"/> <xacro:property name="base_link_z_offset" value="${ground_clearance + chassis_height / 2.0}"/> <xacro:property name="wheel_z_offset" value="${wheel_radius - base_link_z_offset}"/> <xacro:property name="wheel_x_offset" value="${wheel_separation_x / 2.0}"/>
    <xacro:property name="wheel_y_offset" value="${wheel_separation_y / 2.0}"/>

    <xacro:property name="camera_x_offset" value="0"/> <xacro:property name="camera_y_offset" value="0"/> <xacro:property name="camera_z_offset" value="${chassis_height / 2.0 + 0.01}"/> <xacro:property name="camera_size_x" value="0.06"/> <xacro:property name="camera_size_y" value="0.08"/> <xacro:property name="camera_size_z" value="0.04"/> <xacro:property name="base_mass" value="2.5"/> <xacro:property name="wheel_mass" value="0.2"/> <xacro:property name="camera_mass" value="0.3"/> <link name="base_footprint"/>

    <link name="base_link">
        <visual>
            <origin xyz="0 0 0" rpy="0 0 0"/>
            <geometry>
                <box size="${chassis_length} ${chassis_width} ${chassis_height}"/>
            </geometry>
            <material name="blue">
                <color rgba="0.2 0.4 0.8 1"/>
            </material>
        </visual>
        <collision>
            <origin xyz="0 0 0" rpy="0 0 0"/>
            <geometry>
                <box size="${chassis_length} ${chassis_width} ${chassis_height}"/>
            </geometry>
        </collision>
        <inertial>
            <mass value="${base_mass}"/>
            <origin xyz="0 0 0" rpy="0 0 0"/>
            <inertia ixx="${base_mass / 12.0 * (chassis_width*chassis_width + chassis_height*chassis_height)}" ixy="0.0" ixz="0.0"
                     iyy="${base_mass / 12.0 * (chassis_length*chassis_length + chassis_height*chassis_height)}" iyz="0.0"
                     izz="${base_mass / 12.0 * (chassis_length*chassis_length + chassis_width*chassis_width)}" />
        </inertial>
    </link>

    <gazebo reference="base_link">
        <material>Gazebo/Blue</material>
    </gazebo>

    <joint name="base_footprint_joint" type="fixed">
        <parent link="base_footprint"/>
        <child link="base_link"/>
        <origin xyz="0 0 ${base_link_z_offset}" rpy="0 0 0"/>
    </joint>

    <link name="camera_link">
         <visual>
            <origin xyz="0 0 0" rpy="0 0 0"/>
            <geometry>
                <box size="${camera_size_x} ${camera_size_y} ${camera_size_z}"/>
            </geometry>
            <material name="grey">
                <color rgba="0.5 0.5 0.5 1"/>
            </material>
        </visual>
        <collision>
             <origin xyz="0 0 0" rpy="0 0 0"/>
             <geometry>
                <box size="${camera_size_x} ${camera_size_y} ${camera_size_z}"/>
            </geometry>
        </collision>
         <inertial>
            <mass value="${camera_mass}"/>
            <origin xyz="0 0 0" rpy="0 0 0"/>
            <inertia ixx="${camera_mass / 12.0 * (camera_size_y*camera_size_y + camera_size_z*camera_size_z)}" ixy="0.0" ixz="0.0"
                     iyy="${camera_mass / 12.0 * (camera_size_x*camera_size_x + camera_size_z*camera_size_z)}" iyz="0.0"
                     izz="${camera_mass / 12.0 * (camera_size_x*camera_size_x + camera_size_y*camera_size_y)}" />
        </inertial>
    </link>

    <joint name="camera_joint" type="fixed">
        <parent link="base_link"/>
        <child link="camera_link"/>
        <origin xyz="${camera_x_offset} ${camera_y_offset} ${camera_z_offset}" rpy="0 0 0"/> </joint>

    <xacro:macro name="wheel" params="prefix x_reflect y_reflect yaw_reflect">
        <link name="${prefix}_wheel_link">
            <visual>
                <origin xyz="0 0 0" rpy="${PI/2} 0 0"/>
                <geometry>
                    <cylinder radius="${wheel_radius}" length="${wheel_width}"/>
                </geometry>
                <material name="black">
                    <color rgba="0.1 0.1 0.1 1"/>
                </material>
            </visual>
            <collision>
                 <origin xyz="0 0 0" rpy="${PI/2} 0 0"/>
                <geometry>
                    <cylinder radius="${wheel_radius}" length="${wheel_width}"/>
                </geometry>
            </collision>
            <inertial>
                <mass value="${wheel_mass}"/>
                 <origin xyz="0 0 0" rpy="${PI/2} 0 0"/>
                 <inertia ixx="${wheel_mass/12.0*(3*wheel_radius*wheel_radius + wheel_width*wheel_width)}" ixy="0.0" ixz="0.0"
                          iyy="${wheel_mass/2.0*(wheel_radius*wheel_radius)}" iyz="0.0"
                          izz="${wheel_mass/12.0*(3*wheel_radius*wheel_radius + wheel_width*wheel_width)}"/>
            </inertial>
        </link>

        <gazebo reference="${prefix}_wheel_link">
            <material>Gazebo/DarkGrey</material>
            <mu1>0.8</mu1>
            <mu2>0.8</mu2>
        </gazebo>

        <joint name="${prefix}_wheel_joint" type="continuous">
            <parent link="base_link"/>
            <child link="${prefix}_wheel_link"/>
            <origin xyz="${x_reflect * wheel_x_offset} ${y_reflect * wheel_y_offset} ${wheel_z_offset}" rpy="0 0 ${yaw_reflect * PI/4}"/>
            <axis xyz="0 1 0"/>
             <limit effort="100" velocity="100"/> </joint>

        <transmission name="${prefix}_wheel_trans">
            <type>transmission_interface/SimpleTransmission</type>
            <joint name="${prefix}_wheel_joint">
                <hardwareInterface>hardware_interface/VelocityJointInterface</hardwareInterface> </joint>
            <actuator name="${prefix}_wheel_motor">
                <hardwareInterface>hardware_interface/VelocityJointInterface</hardwareInterface>
                <mechanicalReduction>1</mechanicalReduction>
            </actuator>
        </transmission>

    </xacro:macro>

    <xacro:wheel prefix="front_left"  x_reflect="1"  y_reflect="1"  yaw_reflect="1"/>   <xacro:wheel prefix="front_right" x_reflect="1"  y_reflect="-1" yaw_reflect="-1"/>  <xacro:wheel prefix="rear_left"   x_reflect="-1" y_reflect="1"  yaw_reflect="-1"/>  <xacro:wheel prefix="rear_right"  x_reflect="-1" y_reflect="-1" yaw_reflect="1"/>   

    <!-- Gazebo Harmonic Mecanum Drive Plugin -->
    <gazebo>
        <plugin filename="gz-sim-mecanum-drive-system" name="gz::sim::systems::MecanumDrive">
            <front_left_joint>front_left_wheel_joint</front_left_joint>
            <front_right_joint>front_right_wheel_joint</front_right_joint>
            <back_left_joint>rear_left_wheel_joint</back_left_joint>
            <back_right_joint>rear_right_wheel_joint</back_right_joint>
            <wheel_separation>${wheel_separation_y}</wheel_separation>
            <wheelbase>${wheel_separation_x}</wheelbase>
            <wheel_radius>${wheel_radius}</wheel_radius>
            <odom_publish_frequency>50</odom_publish_frequency>
            <!-- Leading slash = global topic scope, not model-namespaced -->
            <topic>/cmd_vel</topic>
            <odom_topic>/odom</odom_topic>
            <tf_topic>/tf</tf_topic>
            <frame_id>odom</frame_id>
            <child_frame_id>base_footprint</child_frame_id>
        </plugin>
        
        <!-- Publish joint states -->
        <plugin filename="gz-sim-joint-state-publisher-system" name="gz::sim::systems::JointStatePublisher">
            <topic>joint_states</topic>
            <joint_name>front_left_wheel_joint</joint_name>
            <joint_name>front_right_wheel_joint</joint_name>
            <joint_name>rear_left_wheel_joint</joint_name>
            <joint_name>rear_right_wheel_joint</joint_name>
        </plugin>
    </gazebo>

</robot>